Workbook

Sheet CTS
B2: CTS y vacaciones
E3: Cambia las celdas amarillas y usa los mismos datos en la app.
B4: CTS a depositar | C4: =C23 -> 1750
B6: 1. Datos editables | C6: Valor
B7: Remuneración mensual computable | C7: 3000 | E7: Sueldo fijo. Mayor que cero y hasta S/ 1,000,000.
B8: Gratificación recibida en el semestre CTS | C8: 3000 | E8: Monto completo, sin bonificación de EsSalud/EPS. Se divide entre 6 una vez.
B9: Meses computables | C9: 6 | E9: De 1 a 6 meses. Periodos CTS: noviembre–abril o mayo–octubre.
B10: Días adicionales | C10: 0 | E10: De 0 a 29 días. Con 6 meses, los días adicionales deben ser 0.
B11: Cumple el promedio mínimo de 4 h/día | C11: Sí | E11: 20 h/semana en cinco días o 24 h/semana en seis días.
B12: Días de vacaciones ya adquiridos | C12: 30 | E12: Días ya adquiridos: supone cumplir el año y el récord vacacional.
B13: Días de vacaciones gozados | C13: 0 | E13: Solo vacaciones pagadas. No se descuentan del tiempo de CTS.
B15: Estado de los datos de CTS | C15: =IF(COUNT(C7:C10)<>4,"Revisar datos",IF(NOT(AND(C7>0,C7<=1000000,ROUND(C7,2)=C7,C8>=0,C8<=1000000,ROUND(C8,2)=C8,C9=INT(C9),C9>=1,C9<=6,C10=INT(C10),C10>=0,C10<=29,OR(C9<6,C10=0),OR(C11="Sí",C11="No"))),"Revisar datos",IF(C11="No","Sin derecho","Listo"))) -> Listo | E15: Si aparece «Revisar datos», corrige los rangos indicados arriba.
B18: 2. Cálculo paso a paso | C18: Soles
B19: Un sexto de la gratificación | C19: =IF(C15="Listo",C8/6,"n.a.") -> 500 | E19: Gratificación recibida / 6
B20: Base para calcular la CTS | C20: =IF(C15="Listo",SUM(C7,C19),"n.a.") -> 3500 | E20: Sueldo + un sexto de gratificación
B21: CTS por meses | C21: =IF(C15="Listo",C20*C9/12,"n.a.") -> 1750 | E21: Base × meses / 12
B22: CTS por días | C22: =IF(C15="Listo",C20*C10/360,"n.a.") -> 0 | E22: Base × días / 360
B23: CTS total | C23: =IF(C15="Listo",ROUND(SUM(C21:C22),2),"n.a.") -> 1750 | E23: Suma de ambas partes, redondeada a 2 decimales
B25: 3. Vacaciones pagadas | C25: Días
B26: Días pendientes | C26: =IF(COUNT(C12:C13)<>2,"Revisar datos",IF(AND(C12=INT(C12),C12>=0,C12<=30,C13=INT(C13),C13>=0,C13<=C12),C12-C13,"Revisar datos")) -> 30 | E26: Prueba con 0 y con 15 días gozados: cambia el saldo, no la CTS.
E28: La base utiliza la gratificación recibida en el semestre de CTS.
E29: No se enlaza automáticamente con el semestre de la otra calculadora.
E30: Régimen privado general, sueldo fijo y tiempo ya computable.
B32: Fuente: guía CTS del MTPE https://cdn.www.gob.pe/uploads/document/file/8050277/6757898-guia_compensacion_tiempo_servicios.pdf?v=1747167296 | E32: Código de referencia: ContentView.swift (24125f0) https://github.com/juniorcueva-star/MovilesAvanzado_JuniorCueva/blob/24125f0/semana%2009/LaboralPeru/LaboralPeru/ContentView.swift
B33: Fuente: jornada mínima para CTS (MTPE) https://www.gob.pe/institucion/mtpe/noticias/1383535-mtpe-trabajadores-del-regimen-privado-que-laboren-4-horas-diarias-en-promedio-tienen-derecho-a-cts

Sheet Gratificacion
B2: Gratificación
E3: Cambia las celdas amarillas y usa los mismos datos en la app.
B4: Importe antes de quinta categoría | C4: =C18 -> 3270
B6: 1. Datos editables | C6: Valor
B7: Remuneración computable | C7: 3000 | E7: Sueldo fijo, hasta S/ 1,000,000. Sin ausencias no computables.
B8: Meses calendario completos | C8: 6 | E8: De 0 a 6 meses completos. Las vacaciones pagadas sí cuentan.
B9: Cobertura EPS | C9: No | E9: Sí = EPS (6.75%). No = EsSalud (9%).
B11: Estado de los datos | C11: =IF(COUNT(C7:C8)<>2,"Revisar datos",IF(AND(C7>0,C7<=1000000,ROUND(C7,2)=C7,C8=INT(C8),C8>=0,C8<=6,OR(C9="Sí",C9="No")),"Listo","Revisar datos")) -> Listo
B14: 2. Cálculo paso a paso | C14: Resultado
B15: Gratificación legal | C15: =IF(C11="Listo",ROUND(C7*C8/6,2),"n.a.") -> 3000 | E15: Sueldo × meses / 6, redondeado a 2 decimales
B16: Tasa de bonificación | C16: =IF(C11="Listo",IF(C9="Sí",0.0675,0.09),"n.a.") -> 0.09 | E16: Tasa según la cobertura de salud
B17: Bonificación extraordinaria | C17: =IF(C11="Listo",ROUND(C15*C16,2),"n.a.") -> 270 | E17: Gratificación × tasa, redondeada a 2 decimales
B18: Total antes de quinta categoría | C18: =IF(C11="Listo",ROUND(SUM(C15,C17),2),"n.a.") -> 3270 | E18: Gratificación + bonificación
E20: Enero–junio para julio; julio–diciembre para Navidad.
E21: No se descuenta AFP/ONP de la gratificación legal ni de su bonificación.
E22: La quinta categoría depende de los ingresos anuales: este importe es previo al IR.
B25: Fuente: gratificaciones y bonificación (Sunafil) https://www.gob.pe/institucion/sunafil/noticias/1413450-mas-de-9-000-denuncias-recibio-la-sunafil-por-falta-de-pago-de-la-gratificacion
B26: Fuente: Ley 30334 https://www.leyes.congreso.gob.pe/Documentos/Leyes/30334.pdf

Sheet Instructores
B2: Pago de instructores
E3: Ejemplo 2026: mismo sueldo todo el año y un empleador.
B4: Total a recibir | C4: =C27 -> 3829.34 | E4: Dos gratificaciones completas. EsSalud. Sin otros ingresos.
E5: Edita solo las celdas amarillas para comparar con la app.
B6: 1. Datos editables | C6: Valor | E6: Parámetros de la app (no cambiar) | F6: Valor
B7: Horas semanales | C7: 23 | E7: Pago por hora | F7: 50
B8: Mes de pago | C8: Octubre | E8: Semanas del ejercicio | F8: 4
B9: Sistema de pensiones | C9: ONP | E9: Horas semanales máximas | F9: 23
B10: AFP seleccionada | C10: Integra | E10: UIT 2026 | F10: 5500
B11: Tipo de comisión AFP | C11: Flujo | E11: UIT deducibles | F11: 7
B12: Número del mes | C12: =IF(COUNTIFS('Quinta 2026'!$C$6:$N$6,C8)=1,MATCH(C8,'Quinta 2026'!$C$6:$N$6,0),"n.a.") -> 10 | E12: Tasa ONP | F12: 0.13
B13: Estado de los datos | C13: =IF(NOT(ISNUMBER(C7)),"Revisar datos",IF(AND(C7>0,C7<=$F$9,ROUND(C7,2)=C7,ISNUMBER(C12),OR(C9="ONP",C9="AFP"),COUNTIFS($E$25:$E$28,C10)=1,OR(C11="Flujo",C11="Saldo")),"Listo","Revisar datos")) -> Listo | E13: Tasa EsSalud | F13: 0.09
E14: RMV enero–septiembre | F14: 1130
B15: 2. Sueldo y descuentos | C15: Soles | E15: RMV octubre–diciembre | F15: 1230
B16: Sueldo bruto | C16: =IF(C13="Listo",ROUND(C7*$F$7*$F$8,2),"n.a.") -> 4600 | E16: Aporte al fondo AFP | F16: 0.1
B17: Aporte ONP / fondo AFP | C17: =IF(C13="Listo",ROUND(C16*IF(C9="ONP",$F$12,$F$16),2),"n.a.") -> 598 | E17: Seguro AFP | F17: 0.0137
B18: Seguro AFP | C18: =IF(C13="Listo",IF(C9="ONP",0,ROUND(MIN(C16,$F$19)*$F$17,2)),"n.a.") -> 0 | E18: Bonificación EsSalud | F18: 0.09
B19: Comisión sobre sueldo | C19: =IF(C13="Listo",IF(OR(C9="ONP",C11="Saldo"),0,ROUND(C16*$F$21,2)),"n.a.") -> 0 | E19: Tope asegurable AFP octubre–diciembre | F19: 12732.7
B20: Descuento total de pensión | C20: =IF(C13="Listo",ROUND(SUM(C17:C19),2),"n.a.") -> 598 | E20: 12 sueldos + 2 gratificaciones | F20: 14
B21: Renta de quinta categoría | C21: =IF(C13="Listo",INDEX('Quinta 2026'!$C$29:$N$29,1,C12),"n.a.") -> 172.66 | E21: Comisión sobre sueldo elegida | F21: =IF(C13="Listo",INDEX($F$25:$F$28,MATCH(C10,$E$25:$E$28,0)),"n.a.") -> 0.0155
B22: Sueldo después de descuentos | C22: =IF(C13="Listo",ROUND(C16-C20-C21,2),"n.a.") -> 3829.34
F23: Sobre sueldo | G23: Anual / saldo
B24: 3. Pagos adicionales | C24: Soles | E24: AFP: tasas de octubre de 2026
B25: Gratificación del mes | C25: =IF(C13="Listo",IF(OR(C12=7,C12=12),C16,0),"n.a.") -> 0 | E25: Habitat | F25: 0.0147 | G25: 0.0125
B26: Bonificación extraordinaria 9% | C26: =IF(C13="Listo",ROUND(C25*$F$18,2),"n.a.") -> 0 | E26: Integra | F26: 0.0155 | G26: 0.0078
B27: Total a recibir | C27: =IF(C13="Listo",ROUND(SUM(C22,C25:C26),2),"n.a.") -> 3829.34 | E27: Prima | F27: 0.016 | G27: 0.0125
E28: Profuturo | F28: 0.0169 | G28: 0.0068
B29: 4. Aporte del empleador | C29: Soles
B30: RMV del mes seleccionado | C30: =IF(C13="Listo",IF(C12>=10,$F$15,$F$14),"n.a.") -> 1230 | E30: Con comisión sobre saldo, el cobro anual se hace del fondo.
B31: EsSalud (no se resta del neto) | C31: =IF(C13="Listo",ROUND(MAX(C16,C30)*$F$13,2),"n.a.") -> 414 | E31: No se suma esa tasa anual al descuento mensual del sueldo.
B33: 5. Detalle de quinta categoría | C33: Resultado | E33: Tramos progresivos de quinta categoría
B34: Ingresos anuales para retención ordinaria | C34: =IF(C13="Listo",INDEX('Quinta 2026'!$C$10:$N$10,1,C12),"n.a.") -> 64814 | E34: Primeras 5 UIT | F34: 0.08 | G34: 5
B35: Deducción de 7 UIT | C35: =IF(C13="Listo",INDEX('Quinta 2026'!$C$11:$N$11,1,C12),"n.a.") -> 38500 | E35: Siguientes 15 UIT | F35: 0.14 | G35: 15
B36: Renta neta anual gravable | C36: =IF(C13="Listo",INDEX('Quinta 2026'!$C$12:$N$12,1,C12),"n.a.") -> 26314 | E36: Siguientes 15 UIT | F36: 0.17 | G36: 15
B37: Impuesto anual por tramos | C37: =IF(C13="Listo",INDEX('Quinta 2026'!$C$20:$N$20,1,C12),"n.a.") -> 2105.12 | E37: Siguientes 10 UIT | F37: 0.2 | G37: 10
B38: Retenciones previas a descontar | C38: =IF(C13="Listo",INDEX('Quinta 2026'!$C$23:$N$23,1,C12),"n.a.") -> 1414.47 | E38: Exceso de 45 UIT | F38: 0.3
B39: Divisor del periodo | C39: =IF(C13="Listo",INDEX('Quinta 2026'!$C$24:$N$24,1,C12),"n.a.") -> 4
B40: Retención ordinaria | C40: =IF(C13="Listo",INDEX('Quinta 2026'!$C$25:$N$25,1,C12),"n.a.") -> 172.66 | E40: Los S/50, las 23 horas y las 4 semanas son reglas del ejercicio.
B41: Retención adicional por bonificación | C41: =IF(C13="Listo",INDEX('Quinta 2026'!$C$28:$N$28,1,C12),"n.a.") -> 0 | E41: Las vacaciones pagadas mantienen el sueldo del mes.
B42: Retención total del mes | C42: =IF(C13="Listo",INDEX('Quinta 2026'!$C$29:$N$29,1,C12),"n.a.") -> 172.66
...

Sheet Quinta 2026
B2: Quinta categoría mes a mes
B3: Sueldo fijo todo 2026. La bonificación extraordinaria se incorpora cuando se paga.
B4: Impuesto anual al cierre | C4: =N40 -> 2138.24 | F4: Retenido anual | G4: =IF(Instructores!C13="Listo",ROUND(SUM(C29:N29),2),"n.a.") -> 2138.24 | J4: Diferencia | K4: =IF(Instructores!C13="Listo",ROUND(C4-G4,2),"n.a.") -> 0
B5: Mes (número) | C5: 1 | D5: 2 | E5: 3 | F5: 4 | G5: 5 | H5: 6 | I5: 7 | J5: 8 | K5: 9 | L5: 10 | M5: 11 | N5: 12
B6: Concepto | C6: Enero | D6: Febrero | E6: Marzo | F6: Abril | G6: Mayo | H6: Junio | I6: Julio | J6: Agosto | K6: Septiembre | L6: Octubre | M6: Noviembre | N6: Diciembre
B8: Sueldo bruto mensual | C8: =IF(Instructores!$C$13="Listo",Instructores!$C$16,"n.a.") -> 4600 | D8: =IF(Instructores!$C$13="Listo",Instructores!$C$16,"n.a.") -> 4600 | E8: =IF(Instructores!$C$13="Listo",Instructores!$C$16,"n.a.") -> 4600 | F8: =IF(Instructores!$C$13="Listo",Instructores!$C$16,"n.a.") -> 4600 | G8: =IF(Instructores!$C$13="Listo",Instructores!$C$16,"n.a.") -> 4600 | H8: =IF(Instructores!$C$13="Listo",Instructores!$C$16,"n.a.") -> 4600 | I8: =IF(Instructores!$C$13="Listo",Instructores!$C$16,"n.a.") -> 4600 | J8: =IF(Instructores!$C$13="Listo",Instructores!$C$16,"n.a.") -> 4600 | ... N8: =IF(Instructores!$C$13="Listo",Instructores!$C$16,"n.a.") -> 4600
B9: Bonificación de julio ya percibida | C9: =IF(ISNUMBER(C8),IF(C$5>7,ROUND(C8*Instructores!$F$18,2),0),"n.a.") -> 0 | D9: =IF(ISNUMBER(D8),IF(D$5>7,ROUND(D8*Instructores!$F$18,2),0),"n.a.") -> 0 | E9: =IF(ISNUMBER(E8),IF(E$5>7,ROUND(E8*Instructores!$F$18,2),0),"n.a.") -> 0 | F9: =IF(ISNUMBER(F8),IF(F$5>7,ROUND(F8*Instructores!$F$18,2),0),"n.a.") -> 0 | G9: =IF(ISNUMBER(G8),IF(G$5>7,ROUND(G8*Instructores!$F$18,2),0),"n.a.") -> 0 | H9: =IF(ISNUMBER(H8),IF(H$5>7,ROUND(H8*Instructores!$F$18,2),0),"n.a.") -> 0 | I9: =IF(ISNUMBER(I8),IF(I$5>7,ROUND(I8*Instructores!$F$18,2),0),"n.a.") -> 0 | J9: =IF(ISNUMBER(J8),IF(J$5>7,ROUND(J8*Instructores!$F$18,2),0),"n.a.") -> 414 | ... N9: =IF(ISNUMBER(N8),IF(N$5>7,ROUND(N8*Instructores!$F$18,2),0),"n.a.") -> 414
B10: Ingresos anuales ordinarios | C10: =IF(ISNUMBER(C8),C8*Instructores!$F$20+C9,"n.a.") -> 64400 | D10: =IF(ISNUMBER(D8),D8*Instructores!$F$20+D9,"n.a.") -> 64400 | E10: =IF(ISNUMBER(E8),E8*Instructores!$F$20+E9,"n.a.") -> 64400 | F10: =IF(ISNUMBER(F8),F8*Instructores!$F$20+F9,"n.a.") -> 64400 | G10: =IF(ISNUMBER(G8),G8*Instructores!$F$20+G9,"n.a.") -> 64400 | H10: =IF(ISNUMBER(H8),H8*Instructores!$F$20+H9,"n.a.") -> 64400 | I10: =IF(ISNUMBER(I8),I8*Instructores!$F$20+I9,"n.a.") -> 64400 | J10: =IF(ISNUMBER(J8),J8*Instructores!$F$20+J9,"n.a.") -> 64814 | ... N10: =IF(ISNUMBER(N8),N8*Instructores!$F$20+N9,"n.a.") -> 64814
B11: Deducción de 7 UIT | C11: =IF(ISNUMBER(C8),Instructores!$F$10*Instructores!$F$11,"n.a.") -> 38500 | D11: =IF(ISNUMBER(D8),Instructores!$F$10*Instructores!$F$11,"n.a.") -> 38500 | E11: =IF(ISNUMBER(E8),Instructores!$F$10*Instructores!$F$11,"n.a.") -> 38500 | F11: =IF(ISNUMBER(F8),Instructores!$F$10*Instructores!$F$11,"n.a.") -> 38500 | G11: =IF(ISNUMBER(G8),Instructores!$F$10*Instructores!$F$11,"n.a.") -> 38500 | H11: =IF(ISNUMBER(H8),Instructores!$F$10*Instructores!$F$11,"n.a.") -> 38500 | I11: =IF(ISNUMBER(I8),Instructores!$F$10*Instructores!$F$11,"n.a.") -> 38500 | J11: =IF(ISNUMBER(J8),Instructores!$F$10*Instructores!$F$11,"n.a.") -> 38500 | ... N11: =IF(ISNUMBER(N8),Instructores!$F$10*Instructores!$F$11,"n.a.") -> 38500
B12: Renta neta anual gravable | C12: =IF(ISNUMBER(C8),MAX(0,C10-C11),"n.a.") -> 25900 | D12: =IF(ISNUMBER(D8),MAX(0,D10-D11),"n.a.") -> 25900 | E12: =IF(ISNUMBER(E8),MAX(0,E10-E11),"n.a.") -> 25900 | F12: =IF(ISNUMBER(F8),MAX(0,F10-F11),"n.a.") -> 25900 | G12: =IF(ISNUMBER(G8),MAX(0,G10-G11),"n.a.") -> 25900 | H12: =IF(ISNUMBER(H8),MAX(0,H10-H11),"n.a.") -> 25900 | I12: =IF(ISNUMBER(I8),MAX(0,I10-I11),"n.a.") -> 25900 | J12: =IF(ISNUMBER(J8),MAX(0,J10-J11),"n.a.") -> 26314 | ... N12: =IF(ISNUMBER(N8),MAX(0,N10-N11),"n.a.") -> 26314
B14: 1. Impuesto anual por tramos
B15: Primeras 5 UIT × 8% | C15: =IF(ISNUMBER(C8),MAX(0,MIN(C12-0,Instructores!$G$34*Instructores!$F$10))*Instructores!$F$34,"n.a.") -> 2072 | D15: =IF(ISNUMBER(D8),MAX(0,MIN(D12-0,Instructores!$G$34*Instructores!$F$10))*Instructores!$F$34,"n.a.") -> 2072 | E15: =IF(ISNUMBER(E8),MAX(0,MIN(E12-0,Instructores!$G$34*Instructores!$F$10))*Instructores!$F$34,"n.a.") -> 2072 | F15: =IF(ISNUMBER(F8),MAX(0,MIN(F12-0,Instructores!$G$34*Instructores!$F$10))*Instructores!$F$34,"n.a.") -> 2072 | G15: =IF(ISNUMBER(G8),MAX(0,MIN(G12-0,Instructores!$G$34*Instructores!$F$10))*Instructores!$F$34,"n.a.") -> 2072 | H15: =IF(ISNUMBER(H8),MAX(0,MIN(H12-0,Instructores!$G$34*Instructores!$F$10))*Instructores!$F$34,"n.a.") -> 2072 | I15: =IF(ISNUMBER(I8),MAX(0,MIN(I12-0,Instructores!$G$34*Instructores!$F$10))*Instructores!$F$34,"n.a.") -> 2072 | J15: =IF(ISNUMBER(J8),MAX(0,MIN(J12-0,Instructores!$G$34*Instructores!$F$10))*Instructores!$F$34,"n.a.") -> 2105.12 | ... N15: =IF(ISNUMBER(N8),MAX(0,MIN(N12-0,Instructores!$G$34*Instructores!$F$10))*Instructores!$F$34,"n.a.") -> 2105.12
B16: Siguientes 15 UIT × 14% | C16: =IF(ISNUMBER(C8),MAX(0,MIN(C12-SUM(Instructores!$G$34:$G$34)*Instructores!$F$10,Instructores!$G$35*Instructores!$F$10))*Instructores!$F$35,"n.a.") -> 0 | D16: =IF(ISNUMBER(D8),MAX(0,MIN(D12-SUM(Instructores!$G$34:$G$34)*Instructores!$F$10,Instructores!$G$35*Instructores!$F$10))*Instructores!$F$35,"n.a.") -> 0 | E16: =IF(ISNUMBER(E8),MAX(0,MIN(E12-SUM(Instructores!$G$34:$G$34)*Instructores!$F$10,Instructores!$G$35*Instructores!$F$10))*Instructores!$F$35,"n.a.") -> 0 | F16: =IF(ISNUMBER(F8),MAX(0,MIN(F12-SUM(Instructores!$G$34:$G$34)*Instructores!$F$10,Instructores!$G$35*Instructores!$F$10))*Instructores!$F$35,"n.a.") -> 0 | G16: =IF(ISNUMBER(G8),MAX(0,MIN(G12-SUM(Instructores!$G$34:$G$34)*Instructores!$F$10,Instructores!$G$35*Instructores!$F$10))*Instructores!$F$35,"n.a.") -> 0 | H16: =IF(ISNUMBER(H8),MAX(0,MIN(H12-SUM(Instructores!$G$34:$G$34)*Instructores!$F$10,Instructores!$G$35*Instructores!$F$10))*Instructores!$F$35,"n.a.") -> 0 | I16: =IF(ISNUMBER(I8),MAX(0,MIN(I12-SUM(Instructores!$G$34:$G$34)*Instructores!$F$10,Instructores!$G$35*Instructores!$F$10))*Instructores!$F$35,"n.a.") -> 0 | J16: =IF(ISNUMBER(J8),MAX(0,MIN(J12-SUM(Instructores!$G$34:$G$34)*Instructores!$F$10,Instructores!$G$35*Instructores!$F$10))*Instructores!$F$35,"n.a.") -> 0 | ... N16: =IF(ISNUMBER(N8),MAX(0,MIN(N12-SUM(Instructores!$G$34:$G$34)*Instructores!$F$10,Instructores!$G$35*Instructores!$F$10))*Instructores!$F$35,"n.a.") -> 0
B17: Siguientes 15 UIT × 17% | C17: =IF(ISNUMBER(C8),MAX(0,MIN(C12-SUM(Instructores!$G$34:$G$35)*Instructores!$F$10,Instructores!$G$36*Instructores!$F$10))*Instructores!$F$36,"n.a.") -> 0 | D17: =IF(ISNUMBER(D8),MAX(0,MIN(D12-SUM(Instructores!$G$34:$G$35)*Instructores!$F$10,Instructores!$G$36*Instructores!$F$10))*Instructores!$F$36,"n.a.") -> 0 | E17: =IF(ISNUMBER(E8),MAX(0,MIN(E12-SUM(Instructores!$G$34:$G$35)*Instructores!$F$10,Instructores!$G$36*Instructores!$F$10))*Instructores!$F$36,"n.a.") -> 0 | F17: =IF(ISNUMBER(F8),MAX(0,MIN(F12-SUM(Instructores!$G$34:$G$35)*Instructores!$F$10,Instructores!$G$36*Instructores!$F$10))*Instructores!$F$36,"n.a.") -> 0 | G17: =IF(ISNUMBER(G8),MAX(0,MIN(G12-SUM(Instructores!$G$34:$G$35)*Instructores!$F$10,Instructores!$G$36*Instructores!$F$10))*Instructores!$F$36,"n.a.") -> 0 | H17: =IF(ISNUMBER(H8),MAX(0,MIN(H12-SUM(Instructores!$G$34:$G$35)*Instructores!$F$10,Instructores!$G$36*Instructores!$F$10))*Instructores!$F$36,"n.a.") -> 0 | I17: =IF(ISNUMBER(I8),MAX(0,MIN(I12-SUM(Instructores!$G$34:$G$35)*Instructores!$F$10,Instructores!$G$36*Instructores!$F$10))*Instructores!$F$36,"n.a.") -> 0 | J17: =IF(ISNUMBER(J8),MAX(0,MIN(J12-SUM(Instructores!$G$34:$G$35)*Instructores!$F$10,Instructores!$G$36*Instructores!$F$10))*Instructores!$F$36,"n.a.") -> 0 | ... N17: =IF(ISNUMBER(N8),MAX(0,MIN(N12-SUM(Instructores!$G$34:$G$35)*Instructores!$F$10,Instructores!$G$36*Instructores!$F$10))*Instructores!$F$36,"n.a.") -> 0
B18: Siguientes 10 UIT × 20% | C18: =IF(ISNUMBER(C8),MAX(0,MIN(C12-SUM(Instructores!$G$34:$G$36)*Instructores!$F$10,Instructores!$G$37*Instructores!$F$10))*Instructores!$F$37,"n.a.") -> 0 | D18: =IF(ISNUMBER(D8),MAX(0,MIN(D12-SUM(Instructores!$G$34:$G$36)*Instructores!$F$10,Instructores!$G$37*Instructores!$F$10))*Instructores!$F$37,"n.a.") -> 0 | E18: =IF(ISNUMBER(E8),MAX(0,MIN(E12-SUM(Instructores!$G$34:$G$36)*Instructores!$F$10,Instructores!$G$37*Instructores!$F$10))*Instructores!$F$37,"n.a.") -> 0 | F18: =IF(ISNUMBER(F8),MAX(0,MIN(F12-SUM(Instructores!$G$34:$G$36)*Instructores!$F$10,Instructores!$G$37*Instructores!$F$10))*Instructores!$F$37,"n.a.") -> 0 | G18: =IF(ISNUMBER(G8),MAX(0,MIN(G12-SUM(Instructores!$G$34:$G$36)*Instructores!$F$10,Instructores!$G$37*Instructores!$F$10))*Instructores!$F$37,"n.a.") -> 0 | H18: =IF(ISNUMBER(H8),MAX(0,MIN(H12-SUM(Instructores!$G$34:$G$36)*Instructores!$F$10,Instructores!$G$37*Instructores!$F$10))*Instructores!$F$37,"n.a.") -> 0 | I18: =IF(ISNUMBER(I8),MAX(0,MIN(I12-SUM(Instructores!$G$34:$G$36)*Instructores!$F$10,Instructores!$G$37*Instructores!$F$10))*Instructores!$F$37,"n.a.") -> 0 | J18: =IF(ISNUMBER(J8),MAX(0,MIN(J12-SUM(Instructores!$G$34:$G$36)*Instructores!$F$10,Instructores!$G$37*Instructores!$F$10))*Instructores!$F$37,"n.a.") -> 0 | ... N18: =IF(ISNUMBER(N8),MAX(0,MIN(N12-SUM(Instructores!$G$34:$G$36)*Instructores!$F$10,Instructores!$G$37*Instructores!$F$10))*Instructores!$F$37,"n.a.") -> 0
B19: Exceso de 45 UIT × 30% | C19: =IF(ISNUMBER(C8),MAX(0,C12-SUM(Instructores!$G$34:$G$37)*Instructores!$F$10)*Instructores!$F$38,"n.a.") -> 0 | D19: =IF(ISNUMBER(D8),MAX(0,D12-SUM(Instructores!$G$34:$G$37)*Instructores!$F$10)*Instructores!$F$38,"n.a.") -> 0 | E19: =IF(ISNUMBER(E8),MAX(0,E12-SUM(Instructores!$G$34:$G$37)*Instructores!$F$10)*Instructores!$F$38,"n.a.") -> 0 | F19: =IF(ISNUMBER(F8),MAX(0,F12-SUM(Instructores!$G$34:$G$37)*Instructores!$F$10)*Instructores!$F$38,"n.a.") -> 0 | G19: =IF(ISNUMBER(G8),MAX(0,G12-SUM(Instructores!$G$34:$G$37)*Instructores!$F$10)*Instructores!$F$38,"n.a.") -> 0 | H19: =IF(ISNUMBER(H8),MAX(0,H12-SUM(Instructores!$G$34:$G$37)*Instructores!$F$10)*Instructores!$F$38,"n.a.") -> 0 | I19: =IF(ISNUMBER(I8),MAX(0,I12-SUM(Instructores!$G$34:$G$37)*Instructores!$F$10)*Instructores!$F$38,"n.a.") -> 0 | J19: =IF(ISNUMBER(J8),MAX(0,J12-SUM(Instructores!$G$34:$G$37)*Instructores!$F$10)*Instructores!$F$38,"n.a.") -> 0 | ... N19: =IF(ISNUMBER(N8),MAX(0,N12-SUM(Instructores!$G$34:$G$37)*Instructores!$F$10)*Instructores!$F$38,"n.a.") -> 0
B20: Impuesto anual ordinario | C20: =IF(ISNUMBER(C8),ROUND(SUM(C15:C19),2),"n.a.") -> 2072 | D20: =IF(ISNUMBER(D8),ROUND(SUM(D15:D19),2),"n.a.") -> 2072 | E20: =IF(ISNUMBER(E8),ROUND(SUM(E15:E19),2),"n.a.") -> 2072 | F20: =IF(ISNUMBER(F8),ROUND(SUM(F15:F19),2),"n.a.") -> 2072 | G20: =IF(ISNUMBER(G8),ROUND(SUM(G15:G19),2),"n.a.") -> 2072 | H20: =IF(ISNUMBER(H8),ROUND(SUM(H15:H19),2),"n.a.") -> 2072 | I20: =IF(ISNUMBER(I8),ROUND(SUM(I15:I19),2),"n.a.") -> 2072 | J20: =IF(ISNUMBER(J8),ROUND(SUM(J15:J19),2),"n.a.") -> 2105.12 | ... N20: =IF(ISNUMBER(N8),ROUND(SUM(N15:N19),2),"n.a.") -> 2105.12
B22: 2. Retención mensual
B23: Retenciones previas a descontar | C23: =IF(ISNUMBER(C8),0,"n.a.") -> 0 | D23: =IF(ISNUMBER(D8),0,"n.a.") -> 0 | E23: =IF(ISNUMBER(E8),0,"n.a.") -> 0 | F23: =IF(ISNUMBER(F8),ROUND(SUM($C$29:$E$29),2),"n.a.") -> 518.01 | G23: =IF(ISNUMBER(G8),ROUND(SUM($C$29:$F$29),2),"n.a.") -> 690.68 | H23: =IF(ISNUMBER(H8),ROUND(SUM($C$29:$F$29),2),"n.a.") -> 690.68 | I23: =IF(ISNUMBER(I8),ROUND(SUM($C$29:$F$29),2),"n.a.") -> 690.68 | J23: =IF(ISNUMBER(J8),ROUND(SUM($C$29:$I$29),2),"n.a.") -> 1241.81 | K23: =IF(ISNUMBER(K8),ROUND(SUM($C$29:$J$29),2),"n.a.") -> 1414.47 | L23: =IF(ISNUMBER(L8),ROUND(SUM($C$29:$J$29),2),"n.a.") -> 1414.47 | M23: =IF(ISNUMBER(M8),ROUND(SUM($C$29:$J$29),2),"n.a.") -> 1414.47 | N23: =IF(ISNUMBER(N8),ROUND(SUM($C$29:$M$29),2),"n.a.") -> 1932.45
B24: Divisor del periodo | C24: 12 | D24: 12 | E24: 12 | F24: 9 | G24: 8 | H24: 8 | I24: 8 | J24: 5 | K24: 4 | L24: 4 | M24: 4 | N24: 1
B25: Retención ordinaria del mes | C25: =IF(ISNUMBER(C8),ROUND(MAX(0,C20-C23)/C24,2),"n.a.") -> 172.67 | D25: =IF(ISNUMBER(D8),ROUND(MAX(0,D20-D23)/D24,2),"n.a.") -> 172.67 | E25: =IF(ISNUMBER(E8),ROUND(MAX(0,E20-E23)/E24,2),"n.a.") -> 172.67 | F25: =IF(ISNUMBER(F8),ROUND(MAX(0,F20-F23)/F24,2),"n.a.") -> 172.67 | G25: =IF(ISNUMBER(G8),ROUND(MAX(0,G20-G23)/G24,2),"n.a.") -> 172.67 | H25: =IF(ISNUMBER(H8),ROUND(MAX(0,H20-H23)/H24,2),"n.a.") -> 172.67 | I25: =IF(ISNUMBER(I8),ROUND(MAX(0,I20-I23)/I24,2),"n.a.") -> 172.67 | J25: =IF(ISNUMBER(J8),ROUND(MAX(0,J20-J23)/J24,2),"n.a.") -> 172.66 | ... N25: =IF(ISNUMBER(N8),ROUND(MAX(0,N20-N23)/N24,2),"n.a.") -> 172.67
B26: Bonificación extraordinaria del mes | C26: =IF(ISNUMBER(C8),IF(OR(C$5=7,C$5=12),ROUND(C8*Instructores!$F$18,2),0),"n.a.") -> 0 | D26: =IF(ISNUMBER(D8),IF(OR(D$5=7,D$5=12),ROUND(D8*Instructores!$F$18,2),0),"n.a.") -> 0 | E26: =IF(ISNUMBER(E8),IF(OR(E$5=7,E$5=12),ROUND(E8*Instructores!$F$18,2),0),"n.a.") -> 0 | F26: =IF(ISNUMBER(F8),IF(OR(F$5=7,F$5=12),ROUND(F8*Instructores!$F$18,2),0),"n.a.") -> 0 | G26: =IF(ISNUMBER(G8),IF(OR(G$5=7,G$5=12),ROUND(G8*Instructores!$F$18,2),0),"n.a.") -> 0 | H26: =IF(ISNUMBER(H8),IF(OR(H$5=7,H$5=12),ROUND(H8*Instructores!$F$18,2),0),"n.a.") -> 0 | I26: =IF(ISNUMBER(I8),IF(OR(I$5=7,I$5=12),ROUND(I8*Instructores!$F$18,2),0),"n.a.") -> 414 | J26: =IF(ISNUMBER(J8),IF(OR(J$5=7,J$5=12),ROUND(J8*Instructores!$F$18,2),0),"n.a.") -> 0 | ... N26: =IF(ISNUMBER(N8),IF(OR(N$5=7,N$5=12),ROUND(N8*Instructores!$F$18,2),0),"n.a.") -> 414
B27: Impuesto con bonificación actual | C27: =IF(ISNUMBER(C8),C40,"n.a.") -> 2072 | D27: =IF(ISNUMBER(D8),D40,"n.a.") -> 2072 | E27: =IF(ISNUMBER(E8),E40,"n.a.") -> 2072 | F27: =IF(ISNUMBER(F8),F40,"n.a.") -> 2072 | G27: =IF(ISNUMBER(G8),G40,"n.a.") -> 2072 | H27: =IF(ISNUMBER(H8),H40,"n.a.") -> 2072 | I27: =IF(ISNUMBER(I8),I40,"n.a.") -> 2105.12 | J27: =IF(ISNUMBER(J8),J40,"n.a.") -> 2105.12 | ... N27: =IF(ISNUMBER(N8),N40,"n.a.") -> 2138.24
B28: Retención adicional por bonificación | C28: =IF(ISNUMBER(C8),ROUND(C27-C20,2),"n.a.") -> 0 | D28: =IF(ISNUMBER(D8),ROUND(D27-D20,2),"n.a.") -> 0 | E28: =IF(ISNUMBER(E8),ROUND(E27-E20,2),"n.a.") -> 0 | F28: =IF(ISNUMBER(F8),ROUND(F27-F20,2),"n.a.") -> 0 | G28: =IF(ISNUMBER(G8),ROUND(G27-G20,2),"n.a.") -> 0 | H28: =IF(ISNUMBER(H8),ROUND(H27-H20,2),"n.a.") -> 0 | I28: =IF(ISNUMBER(I8),ROUND(I27-I20,2),"n.a.") -> 33.12 | J28: =IF(ISNUMBER(J8),ROUND(J27-J20,2),"n.a.") -> 0 | ... N28: =IF(ISNUMBER(N8),ROUND(N27-N20,2),"n.a.") -> 33.12
B29: Total retenido en el mes | C29: =IF(ISNUMBER(C8),ROUND(SUM(C25,C28),2),"n.a.") -> 172.67 | D29: =IF(ISNUMBER(D8),ROUND(SUM(D25,D28),2),"n.a.") -> 172.67 | E29: =IF(ISNUMBER(E8),ROUND(SUM(E25,E28),2),"n.a.") -> 172.67 | F29: =IF(ISNUMBER(F8),ROUND(SUM(F25,F28),2),"n.a.") -> 172.67 | G29: =IF(ISNUMBER(G8),ROUND(SUM(G25,G28),2),"n.a.") -> 172.67 | H29: =IF(ISNUMBER(H8),ROUND(SUM(H25,H28),2),"n.a.") -> 172.67 | I29: =IF(ISNUMBER(I8),ROUND(SUM(I25,I28),2),"n.a.") -> 205.79 | J29: =IF(ISNUMBER(J8),ROUND(SUM(J25,J28),2),"n.a.") -> 172.66 | ... N29: =IF(ISNUMBER(N8),ROUND(SUM(N25,N28),2),"n.a.") -> 205.79
B31: 3. Impuesto al agregar la bonificación
B32: Ingresos anuales + bonificación actual | C32: =IF(ISNUMBER(C8),SUM(C10,C26),"n.a.") -> 64400 | D32: =IF(ISNUMBER(D8),SUM(D10,D26),"n.a.") -> 64400 | E32: =IF(ISNUMBER(E8),SUM(E10,E26),"n.a.") -> 64400 | F32: =IF(ISNUMBER(F8),SUM(F10,F26),"n.a.") -> 64400 | G32: =IF(ISNUMBER(G8),SUM(G10,G26),"n.a.") -> 64400 | H32: =IF(ISNUMBER(H8),SUM(H10,H26),"n.a.") -> 64400 | I32: =IF(ISNUMBER(I8),SUM(I10,I26),"n.a.") -> 64814 | J32: =IF(ISNUMBER(J8),SUM(J10,J26),"n.a.") -> 64814 | ... N32: =IF(ISNUMBER(N8),SUM(N10,N26),"n.a.") -> 65228
B33: Renta neta con bonificación actual | C33: =IF(ISNUMBER(C8),MAX(0,C32-C11),"n.a.") -> 25900 | D33: =IF(ISNUMBER(D8),MAX(0,D32-D11),"n.a.") -> 25900 | E33: =IF(ISNUMBER(E8),MAX(0,E32-E11),"n.a.") -> 25900 | F33: =IF(ISNUMBER(F8),MAX(0,F32-F11),"n.a.") -> 25900 | G33: =IF(ISNUMBER(G8),MAX(0,G32-G11),"n.a.") -> 25900 | H33: =IF(ISNUMBER(H8),MAX(0,H32-H11),"n.a.") -> 25900 | I33: =IF(ISNUMBER(I8),MAX(0,I32-I11),"n.a.") -> 26314 | J33: =IF(ISNUMBER(J8),MAX(0,J32-J11),"n.a.") -> 26314 | ... N33: =IF(ISNUMBER(N8),MAX(0,N32-N11),"n.a.") -> 26728
B35: Primeras 5 UIT × 8% | C35: =IF(ISNUMBER(C8),MAX(0,MIN(C33-0,Instructores!$G$34*Instructores!$F$10))*Instructores!$F$34,"n.a.") -> 2072 | D35: =IF(ISNUMBER(D8),MAX(0,MIN(D33-0,Instructores!$G$34*Instructores!$F$10))*Instructores!$F$34,"n.a.") -> 2072 | E35: =IF(ISNUMBER(E8),MAX(0,MIN(E33-0,Instructores!$G$34*Instructores!$F$10))*Instructores!$F$34,"n.a.") -> 2072 | F35: =IF(ISNUMBER(F8),MAX(0,MIN(F33-0,Instructores!$G$34*Instructores!$F$10))*Instructores!$F$34,"n.a.") -> 2072 | G35: =IF(ISNUMBER(G8),MAX(0,MIN(G33-0,Instructores!$G$34*Instructores!$F$10))*Instructores!$F$34,"n.a.") -> 2072 | H35: =IF(ISNUMBER(H8),MAX(0,MIN(H33-0,Instructores!$G$34*Instructores!$F$10))*Instructores!$F$34,"n.a.") -> 2072 | I35: =IF(ISNUMBER(I8),MAX(0,MIN(I33-0,Instructores!$G$34*Instructores!$F$10))*Instructores!$F$34,"n.a.") -> 2105.12 | J35: =IF(ISNUMBER(J8),MAX(0,MIN(J33-0,Instructores!$G$34*Instructores!$F$10))*Instructores!$F$34,"n.a.") -> 2105.12 | ... N35: =IF(ISNUMBER(N8),MAX(0,MIN(N33-0,Instructores!$G$34*Instructores!$F$10))*Instructores!$F$34,"n.a.") -> 2138.24
B36: Siguientes 15 UIT × 14% | C36: =IF(ISNUMBER(C8),MAX(0,MIN(C33-SUM(Instructores!$G$34:$G$34)*Instructores!$F$10,Instructores!$G$35*Instructores!$F$10))*Instructores!$F$35,"n.a.") -> 0 | D36: =IF(ISNUMBER(D8),MAX(0,MIN(D33-SUM(Instructores!$G$34:$G$34)*Instructores!$F$10,Instructores!$G$35*Instructores!$F$10))*Instructores!$F$35,"n.a.") -> 0 | E36: =IF(ISNUMBER(E8),MAX(0,MIN(E33-SUM(Instructores!$G$34:$G$34)*Instructores!$F$10,Instructores!$G$35*Instructores!$F$10))*Instructores!$F$35,"n.a.") -> 0 | F36: =IF(ISNUMBER(F8),MAX(0,MIN(F33-SUM(Instructores!$G$34:$G$34)*Instructores!$F$10,Instructores!$G$35*Instructores!$F$10))*Instructores!$F$35,"n.a.") -> 0 | G36: =IF(ISNUMBER(G8),MAX(0,MIN(G33-SUM(Instructores!$G$34:$G$34)*Instructores!$F$10,Instructores!$G$35*Instructores!$F$10))*Instructores!$F$35,"n.a.") -> 0 | H36: =IF(ISNUMBER(H8),MAX(0,MIN(H33-SUM(Instructores!$G$34:$G$34)*Instructores!$F$10,Instructores!$G$35*Instructores!$F$10))*Instructores!$F$35,"n.a.") -> 0 | I36: =IF(ISNUMBER(I8),MAX(0,MIN(I33-SUM(Instructores!$G$34:$G$34)*Instructores!$F$10,Instructores!$G$35*Instructores!$F$10))*Instructores!$F$35,"n.a.") -> 0 | J36: =IF(ISNUMBER(J8),MAX(0,MIN(J33-SUM(Instructores!$G$34:$G$34)*Instructores!$F$10,Instructores!$G$35*Instructores!$F$10))*Instructores!$F$35,"n.a.") -> 0 | ... N36: =IF(ISNUMBER(N8),MAX(0,MIN(N33-SUM(Instructores!$G$34:$G$34)*Instructores!$F$10,Instructores!$G$35*Instructores!$F$10))*Instructores!$F$35,"n.a.") -> 0
B37: Siguientes 15 UIT × 17% | C37: =IF(ISNUMBER(C8),MAX(0,MIN(C33-SUM(Instructores!$G$34:$G$35)*Instructores!$F$10,Instructores!$G$36*Instructores!$F$10))*Instructores!$F$36,"n.a.") -> 0 | D37: =IF(ISNUMBER(D8),MAX(0,MIN(D33-SUM(Instructores!$G$34:$G$35)*Instructores!$F$10,Instructores!$G$36*Instructores!$F$10))*Instructores!$F$36,"n.a.") -> 0 | E37: =IF(ISNUMBER(E8),MAX(0,MIN(E33-SUM(Instructores!$G$34:$G$35)*Instructores!$F$10,Instructores!$G$36*Instructores!$F$10))*Instructores!$F$36,"n.a.") -> 0 | F37: =IF(ISNUMBER(F8),MAX(0,MIN(F33-SUM(Instructores!$G$34:$G$35)*Instructores!$F$10,Instructores!$G$36*Instructores!$F$10))*Instructores!$F$36,"n.a.") -> 0 | G37: =IF(ISNUMBER(G8),MAX(0,MIN(G33-SUM(Instructores!$G$34:$G$35)*Instructores!$F$10,Instructores!$G$36*Instructores!$F$10))*Instructores!$F$36,"n.a.") -> 0 | H37: =IF(ISNUMBER(H8),MAX(0,MIN(H33-SUM(Instructores!$G$34:$G$35)*Instructores!$F$10,Instructores!$G$36*Instructores!$F$10))*Instructores!$F$36,"n.a.") -> 0 | I37: =IF(ISNUMBER(I8),MAX(0,MIN(I33-SUM(Instructores!$G$34:$G$35)*Instructores!$F$10,Instructores!$G$36*Instructores!$F$10))*Instructores!$F$36,"n.a.") -> 0 | J37: =IF(ISNUMBER(J8),MAX(0,MIN(J33-SUM(Instructores!$G$34:$G$35)*Instructores!$F$10,Instructores!$G$36*Instructores!$F$10))*Instructores!$F$36,"n.a.") -> 0 | ... N37: =IF(ISNUMBER(N8),MAX(0,MIN(N33-SUM(Instructores!$G$34:$G$35)*Instructores!$F$10,Instructores!$G$36*Instructores!$F$10))*Instructores!$F$36,"n.a.") -> 0
B38: Siguientes 10 UIT × 20% | C38: =IF(ISNUMBER(C8),MAX(0,MIN(C33-SUM(Instructores!$G$34:$G$36)*Instructores!$F$10,Instructores!$G$37*Instructores!$F$10))*Instructores!$F$37,"n.a.") -> 0 | D38: =IF(ISNUMBER(D8),MAX(0,MIN(D33-SUM(Instructores!$G$34:$G$36)*Instructores!$F$10,Instructores!$G$37*Instructores!$F$10))*Instructores!$F$37,"n.a.") -> 0 | E38: =IF(ISNUMBER(E8),MAX(0,MIN(E33-SUM(Instructores!$G$34:$G$36)*Instructores!$F$10,Instructores!$G$37*Instructores!$F$10))*Instructores!$F$37,"n.a.") -> 0 | F38: =IF(ISNUMBER(F8),MAX(0,MIN(F33-SUM(Instructores!$G$34:$G$36)*Instructores!$F$10,Instructores!$G$37*Instructores!$F$10))*Instructores!$F$37,"n.a.") -> 0 | G38: =IF(ISNUMBER(G8),MAX(0,MIN(G33-SUM(Instructores!$G$34:$G$36)*Instructores!$F$10,Instructores!$G$37*Instructores!$F$10))*Instructores!$F$37,"n.a.") -> 0 | H38: =IF(ISNUMBER(H8),MAX(0,MIN(H33-SUM(Instructores!$G$34:$G$36)*Instructores!$F$10,Instructores!$G$37*Instructores!$F$10))*Instructores!$F$37,"n.a.") -> 0 | I38: =IF(ISNUMBER(I8),MAX(0,MIN(I33-SUM(Instructores!$G$34:$G$36)*Instructores!$F$10,Instructores!$G$37*Instructores!$F$10))*Instructores!$F$37,"n.a.") -> 0 | J38: =IF(ISNUMBER(J8),MAX(0,MIN(J33-SUM(Instructores!$G$34:$G$36)*Instructores!$F$10,Instructores!$G$37*Instructores!$F$10))*Instructores!$F$37,"n.a.") -> 0 | ... N38: =IF(ISNUMBER(N8),MAX(0,MIN(N33-SUM(Instructores!$G$34:$G$36)*Instructores!$F$10,Instructores!$G$37*Instructores!$F$10))*Instructores!$F$37,"n.a.") -> 0
B39: Exceso de 45 UIT × 30% | C39: =IF(ISNUMBER(C8),MAX(0,C33-SUM(Instructores!$G$34:$G$37)*Instructores!$F$10)*Instructores!$F$38,"n.a.") -> 0 | D39: =IF(ISNUMBER(D8),MAX(0,D33-SUM(Instructores!$G$34:$G$37)*Instructores!$F$10)*Instructores!$F$38,"n.a.") -> 0 | E39: =IF(ISNUMBER(E8),MAX(0,E33-SUM(Instructores!$G$34:$G$37)*Instructores!$F$10)*Instructores!$F$38,"n.a.") -> 0 | F39: =IF(ISNUMBER(F8),MAX(0,F33-SUM(Instructores!$G$34:$G$37)*Instructores!$F$10)*Instructores!$F$38,"n.a.") -> 0 | G39: =IF(ISNUMBER(G8),MAX(0,G33-SUM(Instructores!$G$34:$G$37)*Instructores!$F$10)*Instructores!$F$38,"n.a.") -> 0 | H39: =IF(ISNUMBER(H8),MAX(0,H33-SUM(Instructores!$G$34:$G$37)*Instructores!$F$10)*Instructores!$F$38,"n.a.") -> 0 | I39: =IF(ISNUMBER(I8),MAX(0,I33-SUM(Instructores!$G$34:$G$37)*Instructores!$F$10)*Instructores!$F$38,"n.a.") -> 0 | J39: =IF(ISNUMBER(J8),MAX(0,J33-SUM(Instructores!$G$34:$G$37)*Instructores!$F$10)*Instructores!$F$38,"n.a.") -> 0 | ... N39: =IF(ISNUMBER(N8),MAX(0,N33-SUM(Instructores!$G$34:$G$37)*Instructores!$F$10)*Instructores!$F$38,"n.a.") -> 0
B40: Impuesto anual con bono actual | C40: =IF(ISNUMBER(C8),ROUND(SUM(C35:C39),2),"n.a.") -> 2072 | D40: =IF(ISNUMBER(D8),ROUND(SUM(D35:D39),2),"n.a.") -> 2072 | E40: =IF(ISNUMBER(E8),ROUND(SUM(E35:E39),2),"n.a.") -> 2072 | F40: =IF(ISNUMBER(F8),ROUND(SUM(F35:F39),2),"n.a.") -> 2072 | G40: =IF(ISNUMBER(G8),ROUND(SUM(G35:G39),2),"n.a.") -> 2072 | H40: =IF(ISNUMBER(H8),ROUND(SUM(H35:H39),2),"n.a.") -> 2072 | I40: =IF(ISNUMBER(I8),ROUND(SUM(I35:I39),2),"n.a.") -> 2105.12 | J40: =IF(ISNUMBER(J8),ROUND(SUM(J35:J39),2),"n.a.") -> 2105.12 | ... N40: =IF(ISNUMBER(N8),ROUND(SUM(N35:N39),2),"n.a.") -> 2138.24
B42: Enero–marzo: /12. Abril: restar enero–marzo y /9. Mayo–julio: restar enero–abril y /8.
B43: Agosto: restar enero–julio y /5. Septiembre–noviembre: restar enero–agosto y /4. Diciembre: ajuste final.
B44: La suma retenida debe coincidir con el impuesto anual que incluye ambas bonificaciones.
